Workbook
Name SegmentaçãodeDados_Country: #N/A
Name SegmentaçãodeDados_Region: #N/A

Sheet base
A1: Year | B1: Country | C1: Region | D1: Gaming_Revenue_BillionUSD | E1: Gaming_Revenue_MillionUSD | F1: Esports_Revenue_MillionUSD | G1: Active_Players_Million | H1: Esports_Viewers_Million | I1: Avg_Spending_USD | J1: Top_Genre | K1: Top_Platform | L1: Esports_Tournaments_Count | M1: Pro_Players_Count | N1: Internet_Penetration_Percent | O1: Internet_Penetration | P1: Avg_Latency_ms | Q1: AR_VR_Adoption_Index | R1: Streaming_Influence_Index | S1: Covid_Impact_Index | T1: Female_Gamer_Percent | U1: Female_Gamer | V1: Mobile_Gaming_Share | W1: Esports_PrizePool_MillionUSD | X1: Gaming_Companies_Count | Y1: CAGR_Gaming | Z1: CAGR_Esports | AA1: ARPU
A2: 2010 | B2: United States | C2: North America | D2: 6.24 | E2: =D2*1000 -> 6240 | F2: 409.6 | G2: 11 | H2: 17.9 | I2: 133.9 | J2: Strategy | K2: Mobile | L2: 104 | M2: 15912 | N2: =O2/100 -> 0.825 | O2: =82.5 -> 82.5 | P2: 95.4 | Q2: 0.13 | R2: 0.1 | S2: 0 | T2: =U2/100 -> 0.13 | U2: 13 | V2: 20 | W2: 34 | X2: 395 | Y2: =VLOOKUP(B2,calculo!$C$5:$D$29,2,FALSE) -> 0.24018869 | Z2: =VLOOKUP(B2,calculo!$C$5:$E$29,3,FALSE) -> 0.30424315 | AA2: =E2/G2 -> 567.27273
A3: 2011 | B3: United States | C3: North America | D3: 7.74 | E3: =D3*1000 -> 7740 | F3: 622.7 | G3: 32.4 | H3: 76.7 | I3: 64.9 | J3: Sports | K3: Console | L3: 63 | M3: 13797 | N3: =O3/100 -> 0.705 | O3: 70.5 | P3: 83.9 | Q3: 0.08 | R3: 0.16 | S3: 0 | T3: =U3/100 -> 0.107 | U3: 10.7 | V3: 23 | W3: 10.2 | X3: 60 | Y3: =VLOOKUP(B3,calculo!$C$5:$D$29,2,FALSE) -> 0.24018869 | Z3: =VLOOKUP(B3,calculo!$C$5:$E$29,3,FALSE) -> 0.30424315 | AA3: =E3/G3 -> 238.88889
A4: 2012 | B4: United States | C4: North America | D4: 9.6 | E4: =D4*1000 -> 9600 | F4: 928.3 | G4: 51.9 | H4: 148.4 | I4: 84.1 | J4: MOBA | K4: Mobile | L4: 22 | M4: 3982 | N4: =O4/100 -> 0.637 | O4: 63.7 | P4: 32.3 | Q4: 0.11 | R4: 0.22 | S4: 0 | T4: =U4/100 -> 0.133 | U4: 13.3 | V4: 26 | W4: 8.5 | X4: 349 | Y4: =VLOOKUP(B4,calculo!$C$5:$D$29,2,FALSE) -> 0.24018869 | Z4: =VLOOKUP(B4,calculo!$C$5:$E$29,3,FALSE) -> 0.30424315 | AA4: =E4/G4 -> 184.9711
A5: 2013 | B5: United States | C5: North America | D5: 11.91 | E5: =D5*1000 -> 11910 | F5: 1321.8 | G5: 50.3 | H5: 92.9 | I5: 76.9 | J5: MOBA | K5: Mobile | L5: 54 | M5: 8262 | N5: =O5/100 -> 0.514 | O5: 51.4 | P5: 88.2 | Q5: 0.14 | R5: 0.28 | S5: 0 | T5: =U5/100 -> 0.128 | U5: 12.8 | V5: 29 | W5: 18.3 | X5: 53 | Y5: =VLOOKUP(B5,calculo!$C$5:$D$29,2,FALSE) -> 0.24018869 | Z5: =VLOOKUP(B5,calculo!$C$5:$E$29,3,FALSE) -> 0.30424315 | AA5: =E5/G5 -> 236.77932
A6: 2014 | B6: United States | C6: North America | D6: 14.77 | E6: =D6*1000 -> 14770 | F6: 869.1 | G6: 13.4 | H6: 21.3 | I6: 69 | J6: Strategy | K6: Mobile | L6: 84 | M6: 24024 | N6: =O6/100 -> 0.934 | O6: 93.4 | P6: 70.5 | Q6: 0.14 | R6: 0.34 | S6: 0 | T6: =U6/100 -> 0.17 | U6: 17 | V6: 32 | W6: 18.3 | X6: 50 | Y6: =VLOOKUP(B6,calculo!$C$5:$D$29,2,FALSE) -> 0.24018869 | Z6: =VLOOKUP(B6,calculo!$C$5:$E$29,3,FALSE) -> 0.30424315 | AA6: =E6/G6 -> 1102.2388
A7: 2015 | B7: United States | C7: North America | D7: 18.31 | E7: =D7*1000 -> 18310 | F7: 944.4 | G7: 26.6 | H7: 60.8 | I7: 65.2 | J7: RPG | K7: Console | L7: 67 | M7: 12596 | N7: =O7/100 -> 0.847 | O7: 84.7 | P7: 30.6 | Q7: 0.06 | R7: 0.4 | S7: 0 | T7: =U7/100 -> 0.173 | U7: 17.3 | V7: 35 | W7: 13.4 | X7: 240 | Y7: =VLOOKUP(B7,calculo!$C$5:$D$29,2,FALSE) -> 0.24018869 | Z7: =VLOOKUP(B7,calculo!$C$5:$E$29,3,FALSE) -> 0.30424315 | AA7: =E7/G7 -> 688.34586
A8: 2016 | B8: United States | C8: North America | D8: 22.71 | E8: =D8*1000 -> 22710 | F8: 3066.3 | G8: 28.1 | H8: 47.5 | I8: 74.5 | J8: Sports | K8: Mobile | L8: 66 | M8: 17490 | N8: =O8/100 -> 0.899 | O8: 89.9 | P8: 60.4 | Q8: 0.21 | R8: 0.46 | S8: 0 | T8: =U8/100 -> 0.205 | U8: 20.5 | V8: 38 | W8: 20.9 | X8: 110 | Y8: =VLOOKUP(B8,calculo!$C$5:$D$29,2,FALSE) -> 0.24018869 | Z8: =VLOOKUP(B8,calculo!$C$5:$E$29,3,FALSE) -> 0.30424315 | AA8: =E8/G8 -> 808.18505
A9: 2017 | B9: United States | C9: North America | D9: 28.17 | E9: =D9*1000 -> 28170 | F9: 2129.6 | G9: 4.3 | H9: 12.7 | I9: 43.3 | J9: FPS | K9: PC | L9: 81 | M9: 18468 | N9: =O9/100 -> 0.729 | O9: 72.9 | P9: 93.1 | Q9: 0.21 | R9: 0.52 | S9: 0 | T9: =U9/100 -> 0.232 | U9: 23.2 | V9: 41 | W9: 12.8 | X9: 416 | Y9: =VLOOKUP(B9,calculo!$C$5:$D$29,2,FALSE) -> 0.24018869 | Z9: =VLOOKUP(B9,calculo!$C$5:$E$29,3,FALSE) -> 0.30424315 | AA9: =E9/G9 -> 6551.1628
A10: 2018 | B10: United States | C10: North America | D10: 34.93 | E10: =D10*1000 -> 34930 | F10: 2455.8 | G10: 56.7 | H10: 152.9 | I10: 113.4 | J10: FPS | K10: PC | L10: 32 | M10: 3680 | N10: =O10/100 -> 0.892 | O10: 89.2 | P10: 85.3 | Q10: 0.38 | R10: 0.58 | S10: 0 | T10: =U10/100 -> 0.279 | U10: 27.9 | V10: 44 | W10: 9.8 | X10: 53 | Y10: =VLOOKUP(B10,calculo!$C$5:$D$29,2,FALSE) -> 0.24018869 | Z10: =VLOOKUP(B10,calculo!$C$5:$E$29,3,FALSE) -> 0.30424315 | AA10: =E10/G10 -> 616.04938
A11: 2019 | B11: United States | C11: North America | D11: 43.32 | E11: =D11*1000 -> 43320 | F11: 3571 | G11: 9.1 | H11: 20.1 | I11: 138.8 | J11: FPS | K11: PC | L11: 5 | M11: 850 | N11: =O11/100 -> 0.887 | O11: 88.7 | P11: 25.5 | Q11: 0.47 | R11: 0.64 | S11: 0 | T11: =U11/100 -> 0.246 | U11: 24.6 | V11: 47 | W11: 1.6 | X11: 465 | Y11: =VLOOKUP(B11,calculo!$C$5:$D$29,2,FALSE) -> 0.24018869 | Z11: =VLOOKUP(B11,calculo!$C$5:$E$29,3,FALSE) -> 0.30424315 | AA11: =E11/G11 -> 4760.4396
A12: 2020 | B12: United States | C12: North America | D12: 53.72 | E12: =D12*1000 -> 53720 | F12: 4133.4 | G12: 16.2 | H12: 29.7 | I12: 56.3 | J12: FPS | K12: Mobile | L12: 92 | M12: 25944 | N12: =O12/100 -> 0.933 | O12: 93.3 | P12: 43.9 | Q12: 0.6 | R12: 1.11 | S12: 0.41 | T12: =U12/100 -> 0.264 | U12: 26.4 | V12: 50 | W12: 23.1 | X12: 395 | Y12: =VLOOKUP(B12,calculo!$C$5:$D$29,2,FALSE) -> 0.24018869 | Z12: =VLOOKUP(B12,calculo!$C$5:$E$29,3,FALSE) -> 0.30424315 | AA12: =E12/G12 -> 3316.0494
A13: 2021 | B13: United States | C13: North America | D13: 66.62 | E13: =D13*1000 -> 66620 | F13: 5630.1 | G13: 38.8 | H13: 111 | I13: 93.7 | J13: Sports | K13: Console | L13: 94 | M13: 19646 | N13: =O13/100 -> 0.843 | O13: 84.3 | P13: 42.8 | Q13: 0.56 | R13: 1.24 | S13: 0.48 | T13: =U13/100 -> 0.282 | U13: 28.2 | V13: 53 | W13: 27.1 | X13: 264 | Y13: =VLOOKUP(B13,calculo!$C$5:$D$29,2,FALSE) -> 0.24018869 | Z13: =VLOOKUP(B13,calculo!$C$5:$E$29,3,FALSE) -> 0.30424315 | AA13: =E13/G13 -> 1717.0103
A14: 2022 | B14: United States | C14: North America | D14: 82.62 | E14: =D14*1000 -> 82620 | F14: 12256.3 | G14: 25.1 | H14: 78.7 | I14: 125.8 | J14: Strategy | K14: Console | L14: 77 | M14: 13321 | N14: =O14/100 -> 0.766 | O14: 76.6 | P14: 75.8 | Q14: 0.65 | R14: 0.82 | S14: 0 | T14: =U14/100 -> 0.328 | U14: 32.8 | V14: 56 | W14: 21.3 | X14: 412 | Y14: =VLOOKUP(B14,calculo!$C$5:$D$29,2,FALSE) -> 0.24018869 | Z14: =VLOOKUP(B14,calculo!$C$5:$E$29,3,FALSE) -> 0.30424315 | AA14: =E14/G14 -> 3291.6335
... A401: 2025 | B401: Singapore | C401: Asia | D401: 84.27 | E401: =D401*1000 -> 84270 | F401: 9115.7 | G401: 46.4 | H401: 107.4 | I401: 135.6 | J401: Strategy | K401: PC | L401: 9 | M401: 2268 | N401: =O401/100 -> 0.559 | O401: 55.9 | P401: 48.2 | Q401: 0.85 | R401: 1 | S401: 0 | T401: =U401/100 -> 0.354 | U401: 35.4 | V401: 65 | W401: 3.4 | X401: 371 | Y401: =VLOOKUP(B401,calculo!$C$5:$D$29,2,FALSE) -> 0.18470612 | Z401: =VLOOKUP(B401,calculo!$C$5:$E$29,3,FALSE) -> 0.20328327 | AA401: =E401/G401 -> 1816.1638

Sheet calculo
B2: Como evoluiu a receita de games e eSports por país e região entre 2010 e 2025?
B3: Qual país teve a maior taxa de crescimento anual (CAGR)? | H3: Region | I3: CAGR Gaming | J3: CAGR Esports
B4: Regiao | C4: Pais | D4: CAGR gaming | E4: CAGR esports | H4: Africa | I4: 0.13809141 | J4: 0.12223248
B5: Africa | C5: South Africa | D5: =((E33/D33)^(1/15)-1) -> 0.13809141 | E5: =((K33/J33)^(1/15)-1) -> 0.12223248 | H5: Asia | I5: 0.1593075 | J5: 0.18245843
B6: Asia | C6: China | D6: =((E35/D35)^(1/15)-1) -> 0.10678689 | E6: =((K35/J35)^(1/15)-1) -> 0.10206917 | H6: Europe | I6: 0.16987418 | J6: 0.1667037
B7: Asia | C7: India | D7: =((E36/D36)^(1/15)-1) -> 0.11797009 | E7: =((K36/J36)^(1/15)-1) -> 0.12846891 | H7: Middle East | I7: 0.10592514 | J7: 0.097947829
B8: Asia | C8: Indonesia | D8: =((E37/D37)^(1/15)-1) -> 0.14460949 | E8: =((K37/J37)^(1/15)-1) -> 0.20582061 | H8: North America | I8: 0.18193961 | J8: 0.21729725
B9: Asia | C9: Japan | D9: =((E38/D38)^(1/15)-1) -> 0.17634741 | E9: =((K38/J38)^(1/15)-1) -> 0.21788855 | H9: Oceania | I9: 0.060091966 | J9: 0.022334714
B10: Asia | C10: Singapore | D10: =((E39/D39)^(1/15)-1) -> 0.18470612 | E10: =((K39/J39)^(1/15)-1) -> 0.20328327 | H10: South America | I10: 0.15941454 | J10: 0.17776702
B11: Asia | C11: South Korea | D11: =((E40/D40)^(1/15)-1) -> 0.19963067 | E11: =((K40/J40)^(1/15)-1) -> 0.24313374 | H11: Total Geral | I11: 0.15674807 | J11: 0.16501724
B12: Asia | C12: Thailand | D12: =((E41/D41)^(1/15)-1) -> 0.18510183 | E12: =((K41/J41)^(1/15)-1) -> 0.17654475
B13: Europe | C13: France | D13: =((E43/D43)^(1/15)-1) -> 0.09070573 | E13: =((K43/J43)^(1/15)-1) -> 0.10460467
B14: Europe | C14: Germany | D14: =((E44/D44)^(1/15)-1) -> 0.17074064 | E14: =((K44/J44)^(1/15)-1) -> 0.10120107
B15: Europe | C15: Italy | D15: =((E45/D45)^(1/15)-1) -> 0.23798636 | E15: =((K45/J45)^(1/15)-1) -> 0.22360173
B16: Europe | C16: Netherlands | D16: =((E46/D46)^(1/15)-1) -> 0.15863193 | E16: =((K46/J46)^(1/15)-1) -> 0.1243439
B17: Europe | C17: Poland | D17: =((E47/D47)^(1/15)-1) -> 0.12237133 | E17: =((K47/J47)^(1/15)-1) -> 0.11557113
B18: Europe | C18: Russia | D18: =((E48/D48)^(1/15)-1) -> 0.15256486 | E18: =((K48/J48)^(1/15)-1) -> 0.16977369
B19: Europe | C19: Spain | D19: =((E49/D49)^(1/15)-1) -> 0.20637919 | E19: =((K49/J49)^(1/15)-1) -> 0.2113399
B20: Europe | C20: Sweden | D20: =((E50/D50)^(1/15)-1) -> 0.24464846 | E20: =((K50/J50)^(1/15)-1) -> 0.30572094
B21: Europe | C21: UK | D21: =((E51/D51)^(1/15)-1) -> 0.14483915 | E21: =((K51/J51)^(1/15)-1) -> 0.1441763
B22: Middle East | C22: Saudi Arabia | D22: =((E53/D53)^(1/15)-1) -> 0.10917839 | E22: =((K53/J53)^(1/15)-1) -> 0.119887
B23: Middle East | C23: Turkey | D23: =((E54/D54)^(1/15)-1) -> 0.10267189 | E23: =((K54/J54)^(1/15)-1) -> 0.076008662
B24: North America | C24: Canada | D24: =((E56/D56)^(1/15)-1) -> 0.19962362 | E24: =((K56/J56)^(1/15)-1) -> 0.24464552
B25: North America | C25: Mexico | D25: =((E57/D57)^(1/15)-1) -> 0.10600652 | E25: =((K57/J57)^(1/15)-1) -> 0.10300308
B26: North America | C26: United States | D26: =((E58/D58)^(1/15)-1) -> 0.24018869 | E26: =((K58/J58)^(1/15)-1) -> 0.30424315
B27: Oceania | C27: Australia | D27: =((E60/D60)^(1/15)-1) -> 0.060091966 | E27: =((K60/J60)^(1/15)-1) -> 0.022334714
B28: South America | C28: Argentina | D28: =((E62/D62)^(1/15)-1) -> 0.073080164 | E28: =((K62/J62)^(1/15)-1) -> 0.071539348
B29: South America | C29: Brazil | D29: =((E63/D63)^(1/15)-1) -> 0.24574893 | E29: =((K63/J63)^(1/15)-1) -> 0.2839947
B31: Soma de Gaming_Revenue_MillionUSD | D31: Year | H31: Soma de Esports_Revenue_MillionUSD | J31: Year
B32: Region | C32: Country | D32: 2010 | E32: 2025 | F32: Total Geral | H32: Region | I32: Country | J32: 2010 | K32: 2025 | L32: Total Geral
B33: Africa | C33: South Africa | D33: 12490 | E33: 86940 | F33: 99430 | H33: Africa | I33: South Africa | J33: 1397.6 | K33: 7881.8 | L33: 9279.4
B34: Africa Total | D34: 12490 | E34: 86940 | F34: 99430 | H34: Africa Total | J34: 1397.6 | K34: 7881.8 | L34: 9279.4
B35: Asia | C35: China | D35: 14630 | E35: 67020 | F35: 81650 | H35: Asia | I35: China | J35: 1387.7 | K35: 5962.5 | L35: 7350.2
C36: India | D36: 7960 | E36: 42400 | F36: 50360 | I36: India | J36: 1001.9 | K36: 6140 | L36: 7141.9
C37: Indonesia | D37: 4800 | E37: 36400 | F37: 41200 | I37: Indonesia | J37: 241.5 | K37: 4000.9 | L37: 4242.4
C38: Japan | D38: 9030 | E38: 103210 | F38: 112240 | I38: Japan | J38: 748.1 | K38: 14390.4 | L38: 15138.5
C39: Singapore | D39: 6630 | E39: 84270 | F39: 90900 | I39: Singapore | J39: 567.9 | K39: 9115.7 | L39: 9683.6
C40: South Korea | D40: 12290 | E40: 188480 | F40: 200770 | I40: South Korea | J40: 1069.5 | K40: 27986.5 | L40: 29056
C41: Thailand | D41: 7220 | E41: 92230 | F41: 99450 | I41: Thailand | J41: 986.1 | K41: 11299.2 | L41: 12285.3
B42: Asia Total | D42: 62560 | E42: 614010 | F42: 676570 | H42: Asia Total | J42: 6002.7 | K42: 78895.2 | L42: 84897.9
...

Sheet dashboard
U1: Country | V1: (Tudo)
U3: Year | V3: E-sports | W3: Gaming
U4: 2010 | V4: 21134.5 | W4: 214200
U5: 2011 | V5: 25080.3 | W5: 249170
U6: 2012 | V6: 24551.5 | W6: 290400
U7: 2013 | V7: 34951.7 | W7: 339020
U8: 2014 | V8: 41072.4 | W8: 396420
U9: 2015 | V9: 44970.5 | W9: 464330
U10: 2016 | V10: 53380.9 | W10: 544700
U11: 2017 | V11: 54950.4 | W11: 640110
U12: 2018 | V12: 78699.2 | W12: 753410
U13: 2019 | V13: 96484.6 | W13: 888190
U14: 2020 | V14: 103929.8 | W14: 1048740
U15: 2021 | V15: 128319.7 | W15: 1240210
... U19: 2025 | V19: 278007 | W19: 2462490
U20: Total Geral | V20: 1519159.1 | W20: 14812670
